<mujoco model="urdf_assquadrupedembly">
  <option iterations="50" timestep="0.001" solver="PGS" gravity="0 0 -9.81" />

  <compiler angle="radian" meshdir="meshes" eulerseq="zyx" autolimits="true" />

  <default>
    <joint limited="true" damping="0.01" armature="0.01" frictionloss="0.01" />
    <geom condim="4" contype="1" conaffinity="15" friction="0.9 0.2 0.2" solref="0.001 2" />
    <motor ctrllimited="true" />
    <equality solref="0.001 2" />
    <default class="visualgeom">
      <geom material="visualgeom" condim="1" contype="0" conaffinity="0" />
    </default>
  </default>

  <asset>
    <mesh name="base_link" content_type="model/stl" file="base_link.stl" scale="0.001 0.001 0.001" />
    <mesh name="thigh_link1_1" content_type="model/stl" file="thigh_link1_1.stl" scale="0.001 0.001 0.001" />
    <mesh name="thigh_link2_1" content_type="model/stl" file="thigh_link2_1.stl" scale="0.001 0.001 0.001" />
    <mesh name="thigh_link4_1" content_type="model/stl" file="thigh_link4_1.stl" scale="0.001 0.001 0.001" />
    <mesh name="thigh_link3_1" content_type="model/stl" file="thigh_link3_1.stl" scale="0.001 0.001 0.001" />
    <mesh name="calf_link1_1" content_type="model/stl" file="calf_link1_1.stl" scale="0.001 0.001 0.001" />
    <mesh name="calf_link4_1" content_type="model/stl" file="calf_link4_1.stl" scale="0.001 0.001 0.001" />
    <mesh name="calf_link3_1" content_type="model/stl" file="calf_link3_1.stl" scale="0.001 0.001 0.001" />
    <mesh name="calf_link2_1" content_type="model/stl" file="calf_link2_1.stl" scale="0.001 0.001 0.001" />
    <mesh name="hip_abduction4_1" content_type="model/stl" file="hip_abduction4_1.stl" scale="0.001 0.001 0.001" />
    <mesh name="hip_abduction3_1" content_type="model/stl" file="hip_abduction3_1.stl" scale="0.001 0.001 0.001" />
    <mesh name="hip_abduction2_1" content_type="model/stl" file="hip_abduction2_1.stl" scale="0.001 0.001 0.001" />
    <mesh name="hip_abduction_1" content_type="model/stl" file="hip_abduction_1.stl" scale="0.001 0.001 0.001" />
    <texture name="texplane" type="2d" builtin="checker" rgb1=".0 .0 .0" rgb2=".8 .8 .8" width="100" height="100" />
    <material name="matplane" reflectance="0." texture="texplane" texrepeat="1 1" texuniform="true" />
    <material name="visualgeom" rgba="0.5 0.9 0.2 1" />
  </asset>

  <worldbody>
  
    <light directional="true" diffuse="0.4 0.4 0.4" specular="0.1 0.1 0.1" pos="0 0 5.0" dir="0 0 -1" castshadow="false" />
    <light directional="true" diffuse="0.6 0.6 0.6" specular="0.2 0.2 0.2" pos="0 0 4" dir="0 0 -1" />
    <geom name="ground" type="plane" pos="0 0 0" size="100 100 0.001" quat="1 0 0 0" material="matplane" condim="3" conaffinity="15" />
    <camera name="fixed" pos="0 -3.0 1.0345332772362816" xyaxes="1 0 0 0 0 1" />
    <camera name="track" mode="trackcom" pos="0 -3.0 1.0345332772362816" xyaxes="1 0 0 0 0 1" />

    <body name="root" pos="0 0 0.8" quat="1 0 0 0">
      <freejoint name="root" />
      <site name="imu" size="0.01" pos="0 0 0" />
      <geom type="mesh" mesh="base_link" contype="1" conaffinity="0" density="0" group="1" class="visualgeom" />
      <geom type="mesh" rgba="" mesh="base_link" />
      <!-- back right leg -->
      <body name="hip_abduction4_1" pos="0.11 -0.553 4e-06">
        <inertial pos="0.000430933 -0.0443461 0.000932954" quat="0.863929 0.502904 0.0254162 0.00830123" mass="0.8" diaginertia="0.00308223 0.00220416 0.00193961" />
        <joint name="Revolute_9" pos="0 0 0" axis="0 -1 0" range="-0.7854 0.7854" />
        <geom pos="-0.11 0.553 -4e-06" quat="1 0 0 0" type="mesh" mesh="hip_abduction4_1" contype="1" conaffinity="0" density="0" group="1" class="visualgeom" />
        <geom type="mesh" rgba="" mesh="hip_abduction4_1" pos="-0.11 0.553 -4e-06" quat="1 0 0 0" />
        <body name="thigh_link1_1" pos="0.0274 -0.058 0">
          <inertial pos="0.0450236 -0.0317711 -0.0485772" quat="0.955978 -0.284738 -0.0662545 0.0253302" mass="2.2" diaginertia="0.0305159 0.0299484 0.00400472" />
          <joint name="Revolute_1" pos="0 0 0" axis="1 0 0" range="-0.7854 0.7854" />
          <geom pos="-0.1374 0.611 -4e-06" quat="1 0 0 0" type="mesh" mesh="thigh_link1_1" contype="1" conaffinity="0" density="0" group="1" class="visualgeom" />
          <geom type="mesh" rgba="" mesh="thigh_link1_1" pos="-0.1374 0.611 -4e-06" quat="1 0 0 0" />
          <body name="calf_link1_1" pos="0.0541 -0.15 -0.259808">
            <inertial pos="0.0109923 0.0867484 -0.134266" quat="0.954735 0.297455 -0.000460521 0.0012061" mass="0.8" diaginertia="0.013917 0.0137956 0.000235429" />
            <joint name="Revolute_5" pos="0 0 0" axis="1 0 0 " range="-0.7854 0.7854" />
            <geom pos="-0.1915 0.761 0.259804" type="mesh" mesh="calf_link1_1" contype="1" conaffinity="0" density="0" group="1" class="visualgeom" />
            <geom type="mesh" rgba="" mesh="calf_link1_1" pos="-0.1915 0.761 0.259804" />
          </body>
        </body>
      </body>
      <!-- back left leg -->
      <body name="hip_abduction3_1" pos="-0.11 -0.553 4e-06">
        <inertial pos="-0.000430933 -0.0443461 -0.000932738" quat="0.502904 0.863929 -0.00830123 -0.0254162" mass="0.8" diaginertia="0.00308223 0.00220416 0.00193961" />
        <joint name="Revolute_10" pos="0 0 0" axis="0 -1 0" range="-0.7854 0.7854"/>
        <geom pos="0.11 0.553 -4e-06" quat="1 0 0 0" type="mesh" mesh="hip_abduction3_1" contype="1" conaffinity="0" density="0" group="1" class="visualgeom" />
        <geom type="mesh" rgba="" mesh="hip_abduction3_1" pos="0.11 0.553 -4e-06" quat="1 0 0 0" />
        <body name="thigh_link3_1" pos="-0.0274 -0.058 0">
          <inertial pos="-0.0450235 -0.0317709 -0.0485768" quat="0.955978 -0.284738 0.0662545 -0.0253302" mass="2.2" diaginertia="0.0305159 0.0299484 0.00400472" />
          <joint name="Revolute_4" pos="0 0 0" axis="-1 0 0" range="-0.7854 0.7854"/>
          <geom pos="0.1374 0.611 -4e-06" type="mesh" mesh="thigh_link3_1" contype="1" conaffinity="0" density="0" group="1" class="visualgeom" />
          <geom type="mesh" rgba="" mesh="thigh_link3_1" pos="0.1374 0.611 -4e-06" />
          <body name="calf_link3_1" pos="-0.0541 -0.15 -0.259808">
            <inertial pos="-0.0109923 0.0867484 -0.134266" quat="0.954735 0.297455 0.000460521 -0.0012061" mass="0.8" diaginertia="0.013917 0.0137956 0.000235429" />
            <joint name="Revolute_7" pos="0 0 0" axis="1 0 0" range="-0.7854 0.7854"/>
            <geom pos="0.1915 0.761 0.259804" type="mesh" mesh="calf_link3_1" contype="1" conaffinity="0" density="0" group="1" class="visualgeom" />
            <geom type="mesh" rgba="" mesh="calf_link3_1" pos="0.1915 0.761 0.259804" />
          </body>
        </body>
      </body>
      <!-- front left leg -->
      <body name="hip_abduction2_1" pos="-0.11 0.053 4e-06">
        <inertial pos="-0.000430933 0.0443461 0.000932954" quat="0.502904 0.863929 0.00830123 0.0254162" mass="0.8" diaginertia="0.00308223 0.00220416 0.00193961" />
        <joint name="Revolute_11" pos="0 0 0" axis="0 1 0" range="-0.7854 0.7854"/>
        <geom pos="0.11 -0.053 -4e-06" quat="1 0 0 0" type="mesh" mesh="hip_abduction2_1" contype="1" conaffinity="0" density="0" group="1" class="visualgeom" />
        <geom type="mesh" rgba="" mesh="hip_abduction2_1" pos="0.11 -0.053 -4e-06" quat="1 0 0 0" />
        <body name="thigh_link4_1" pos="-0.0274 0.058 0">
          <inertial pos="-0.0450235 -0.0317709 -0.0485768" quat="0.955978 -0.284738 0.0662545 -0.0253302" mass="2.2" diaginertia="0.0305159 0.0299484 0.00400472" />
          <joint name="Revolute_3" pos="0 0 0" axis="-1 0 0" range="-0.7854 0.7854"/>
          <geom pos="0.1374 -0.111 -4e-06" quat="1 0 0 0" type="mesh" mesh="thigh_link4_1" contype="1" conaffinity="0" density="0" group="1" class="visualgeom" />
          <geom type="mesh" rgba="" mesh="thigh_link4_1" pos="0.1374 -0.111 -4e-06" quat="1 0 0 0" />
          <body name="calf_link4_1" pos="-0.0541 -0.15 -0.259808">
            <inertial pos="-0.0109923 0.0867484 -0.134266" quat="0.954735 0.297455 0.000460521 -0.0012061" mass="0.8" diaginertia="0.013917 0.0137956 0.000235429" />
            <joint name="Revolute_6" pos="0 0 0" axis="1 0 0" range="-0.7854 0.7854"/>
            <geom pos="0.1915 0.039 0.259804" type="mesh" mesh="calf_link4_1" contype="1" conaffinity="0" density="0" group="1" class="visualgeom" />
            <geom type="mesh" rgba="" mesh="calf_link4_1" pos="0.1915 0.039 0.259804" />
          </body>
        </body>
      </body>
      <!-- front right leg -->
      <body name="hip_abduction_1" pos="0.11 0.053 4e-06">
        <inertial pos="0.000430933 0.0443461 -0.000932738" quat="0.863929 0.502904 -0.0254162 -0.00830123" mass="0.8" diaginertia="0.00308223 0.00220416 0.00193961" />
        <joint name="Revolute_12" pos="0 0 0" axis="0 1 0" range="-0.7854 0.7854"/>
        <geom pos="-0.11 -0.053 -4e-06" quat="1 0 0 0" type="mesh" mesh="hip_abduction_1" contype="1" conaffinity="0" density="0" group="1" class="visualgeom" />
        <geom type="mesh" rgba="" mesh="hip_abduction_1" pos="-0.11 -0.053 -4e-06" quat="1 0 0 0" />
        <body name="thigh_link2_1" pos="0.0274 0.058 0">
          <inertial pos="0.0450236 -0.0317711 -0.0485772" quat="0.955978 -0.284738 -0.0662545 0.0253302" mass="2.2" diaginertia="0.0305159 0.0299484 0.00400472" />
          <joint name="Revolute_2" pos="0 0 0" axis="1 0 0" range="-0.7854 0.7854"/>
          <geom pos="-0.1374 -0.111 -4e-06" type="mesh" mesh="thigh_link2_1" contype="1" conaffinity="0" density="0" group="1" class="visualgeom" />
          <geom type="mesh" rgba="" mesh="thigh_link2_1" pos="-0.1374 -0.111 -4e-06" />
          <body name="calf_link2_1" pos="0.0765 -0.15 -0.259808">
            <inertial pos="-0.0110077 0.0867484 -0.134266" quat="0.954735 0.297455 -0.000460521 0.0012061" mass="0.8" diaginertia="0.013917 0.0137956 0.000235429" />
            <joint name="Revolute_8" pos="0 0 0" axis="-1 0 0" range="-0.7854 0.7854"/>
            <geom pos="-0.2139 0.039 0.259804" type="mesh" mesh="calf_link2_1" contype="1" conaffinity="0" density="0" group="1" class="visualgeom" />
            <geom type="mesh" rgba="" mesh="calf_link2_1" pos="-0.2139 0.039 0.259804" />
          </body>
        </body>
      </body>
    </body>
  </worldbody>

  <actuator>
    <motor name="Revolute_9" joint="Revolute_9" ctrllimited="true" ctrlrange="-1 1" gear="1" />
    <motor name="Revolute_1" joint="Revolute_1" ctrllimited="true" ctrlrange="-1 1" gear="1" />
    <motor name="Revolute_5" joint="Revolute_5" ctrllimited="true" ctrlrange="-1 1" gear="1" />
    <motor name="Revolute_10" joint="Revolute_10" ctrllimited="true" ctrlrange="-1 1" gear="1" />
    <motor name="Revolute_4" joint="Revolute_4" ctrllimited="true" ctrlrange="-1 1" gear="1" />
    <motor name="Revolute_7" joint="Revolute_7" ctrllimited="true" ctrlrange="-1 1" gear="1" />
    <motor name="Revolute_11" joint="Revolute_11" ctrllimited="true" ctrlrange="-1 1" gear="1" />
    <motor name="Revolute_3" joint="Revolute_3" ctrllimited="true" ctrlrange="-1 1" gear="1" />
    <motor name="Revolute_6" joint="Revolute_6" ctrllimited="true" ctrlrange="-1 1" gear="1" />
    <motor name="Revolute_12" joint="Revolute_12" ctrllimited="true" ctrlrange="-1 1" gear="1" />
    <motor name="Revolute_2" joint="Revolute_2" ctrllimited="true" ctrlrange="-1 1" gear="1" />
    <motor name="Revolute_8" joint="Revolute_8" ctrllimited="true" ctrlrange="-1 1" gear="1" />
  </actuator>

  <sensor>
    <actuatorpos name="Revolute_9_p" actuator="Revolute_9" />
    <actuatorvel name="Revolute_9_v" actuator="Revolute_9" />
    <actuatorfrc name="Revolute_9_f" actuator="Revolute_9" noise="0.001" />
    <actuatorpos name="Revolute_1_p" actuator="Revolute_1" />
    <actuatorvel name="Revolute_1_v" actuator="Revolute_1" />
    <actuatorfrc name="Revolute_1_f" actuator="Revolute_1" noise="0.001" />
    <actuatorpos name="Revolute_5_p" actuator="Revolute_5" />
    <actuatorvel name="Revolute_5_v" actuator="Revolute_5" />
    <actuatorfrc name="Revolute_5_f" actuator="Revolute_5" noise="0.001" />
    <actuatorpos name="Revolute_10_p" actuator="Revolute_10" />
    <actuatorvel name="Revolute_10_v" actuator="Revolute_10" />
    <actuatorfrc name="Revolute_10_f" actuator="Revolute_10" noise="0.001" />
    <actuatorpos name="Revolute_4_p" actuator="Revolute_4" />
    <actuatorvel name="Revolute_4_v" actuator="Revolute_4" />
    <actuatorfrc name="Revolute_4_f" actuator="Revolute_4" noise="0.001" />
    <actuatorpos name="Revolute_7_p" actuator="Revolute_7" />
    <actuatorvel name="Revolute_7_v" actuator="Revolute_7" />
    <actuatorfrc name="Revolute_7_f" actuator="Revolute_7" noise="0.001" />
    <actuatorpos name="Revolute_11_p" actuator="Revolute_11" />
    <actuatorvel name="Revolute_11_v" actuator="Revolute_11" />
    <actuatorfrc name="Revolute_11_f" actuator="Revolute_11" noise="0.001" />
    <actuatorpos name="Revolute_3_p" actuator="Revolute_3" />
    <actuatorvel name="Revolute_3_v" actuator="Revolute_3" />
    <actuatorfrc name="Revolute_3_f" actuator="Revolute_3" noise="0.001" />
    <actuatorpos name="Revolute_6_p" actuator="Revolute_6" />
    <actuatorvel name="Revolute_6_v" actuator="Revolute_6" />
    <actuatorfrc name="Revolute_6_f" actuator="Revolute_6" noise="0.001" />
    <actuatorpos name="Revolute_12_p" actuator="Revolute_12" />
    <actuatorvel name="Revolute_12_v" actuator="Revolute_12" />
    <actuatorfrc name="Revolute_12_f" actuator="Revolute_12" noise="0.001" />
    <actuatorpos name="Revolute_2_p" actuator="Revolute_2" />
    <actuatorvel name="Revolute_2_v" actuator="Revolute_2" />
    <actuatorfrc name="Revolute_2_f" actuator="Revolute_2" noise="0.001" />
    <actuatorpos name="Revolute_8_p" actuator="Revolute_8" />
    <actuatorvel name="Revolute_8_v" actuator="Revolute_8" />
    <actuatorfrc name="Revolute_8_f" actuator="Revolute_8" noise="0.001" />
    <framequat name="orientation" objtype="site" noise="0.001" objname="imu" />
    <gyro name="angular-velocity" site="imu" noise="0.005" cutoff="34.9" />
  </sensor>
</mujoco>