<?xml version='1.0' encoding='utf-8'?>
<robot name="urdf_assembly_v3">
  <material name="silver">
    <color rgba="0.700 0.700 0.700 1.000" />
  </material>
  <!-- <link name="base"/> -->
  <!-- Fixed joint that rotates the whole robot 180° about X -->
  <link name="world"/>

  <link name="trunk">
    <inertial>
      <origin xyz="0.180036 -0.000024 -0.007962"/>
      <mass value="13.252419"/>
      <inertia ixx="0.11610000" ixy="-0.00006689" ixz="-0.00004903"
              iyy="0.26320000" iyz="0.00001886" izz="0.33710000"/>
    </inertial>
    <visual>
      <origin rpy="0 0 0" xyz="0 0 0" />
      <geometry>
        <mesh filename="meshes/trunk.stl" scale="0.001 0.001 0.001" />
      </geometry>
      <material name="silver" />
    </visual>
    <!-- <collision>
      <origin rpy="0 0 0" xyz="0 0 0" />
      <geometry>
        <mesh filename="meshes/trunk.stl" scale="0.001 0.001 0.001" />
      </geometry>
    </collision> -->
  </link>
  <link name="FL_hip">
    <inertial>
      <origin xyz="-0.056864 0.001156 0.001126"/>
      <mass value="1.008402"/>
      <inertia ixx="0.00123900" ixy="0.00001874" ixz="-0.00000002"
              iyy="0.00203800" iyz="0.00000005" izz="0.00147300"/>
    </inertial>
    <visual>
      <origin rpy="0 0 0" xyz="0.059 0.098894 0.00113" />
      <geometry>
        <mesh filename="meshes/FL_hip.stl" scale="0.001 0.001 0.001" />
      </geometry>
      <material name="silver" />
    </visual>
    <!-- <collision>
      <origin rpy="0 0 0" xyz="0.059 0.098894 0.00113" />
      <geometry>
        <mesh filename="meshes/FL_hip.stl" scale="0.001 0.001 0.001" />
      </geometry>
    </collision> -->
  </link>
  <link name="RL_hip">
    <inertial>
      <origin xyz="0.056564 0.001156 0.001134"/>
      <mass value="1.008402"/>
      <inertia ixx="0.00123900" ixy="-0.00001874" ixz="-0.00000002"
              iyy="0.00203800" iyz="-0.00000005" izz="0.00147300"/>
    </inertial>
    <visual>
      <origin rpy="0 0 0" xyz="-0.419 0.098894 0.00113" />
      <geometry>
        <mesh filename="meshes/RL_hip.stl" scale="0.001 0.001 0.001" />
      </geometry>
      <material name="silver" />
    </visual>
    <!-- <collision>
      <origin rpy="0 0 0" xyz="-0.419 0.098894 0.00113" />
      <geometry>
        <mesh filename="meshes/RL_hip.stl" scale="0.001 0.001 0.001" />
      </geometry>
    </collision> -->
  </link>
  <link name="RR_hip">
    <inertial>
      <origin xyz="0.056564 -0.003368 0.001133"/>
      <mass value="1.008392"/>
      <inertia ixx="0.00123900" ixy="0.00001874" ixz="-0.00000002"
              iyy="0.00203800" iyz="0.00000005" izz="0.00147300"/>
    </inertial>
    <visual>
      <origin rpy="0 0 0" xyz="-0.419 -0.101106 0.00113" />
      <geometry>
        <mesh filename="meshes/RR_hip.stl" scale="0.001 0.001 0.001" />
      </geometry>
      <material name="silver" />
    </visual>
    <!-- <collision>
      <origin rpy="0 0 0" xyz="-0.419 -0.101106 0.00113" />
      <geometry>
        <mesh filename="meshes/RR_hip.stl" scale="0.001 0.001 0.001" />
      </geometry>
    </collision> -->
  </link>
  <link name="FR_hip">
    <inertial>
      <origin xyz="-0.056864 -0.003368 0.001127"/>
      <mass value="1.008392"/>
      <inertia ixx="0.00123900" ixy="-0.00001874" ixz="-0.00000002"
              iyy="0.00203800" iyz="-0.00000005" izz="0.00147300"/>
    </inertial>
    <visual>
      <origin rpy="0 0 0" xyz="0.059 -0.101106 0.00113" />
      <geometry>
        <mesh filename="meshes/FR_hip.stl" scale="0.001 0.001 0.001" />
      </geometry>
      <material name="silver" />
    </visual>
    <!-- <collision>
      <origin rpy="0 0 0" xyz="0.059 -0.101106 0.00113" />
      <geometry>
        <mesh filename="meshes/FR_hip.stl" scale="0.001 0.001 0.001" />
      </geometry>
    </collision> -->
  </link>
  <link name="FR_thigh">
    <inertial>
      <origin xyz="0.041847 0.044995 -0.007447"/>
      <mass value="2.226976"/>
      <inertia ixx="0.00428900" ixy="-0.00242400" ixz="0.00381700"
              iyy="0.02280000" iyz="0.00050890" izz="0.02121000"/>
    </inertial>
    <visual>
      <origin rpy="0 0 0" xyz="0.121 -0.128506 0.00113" />
      <geometry>
        <mesh filename="meshes/FR_thigh.stl" scale="0.001 0.001 0.001" />
      </geometry>
      <material name="silver" />
    </visual>
    <!-- <collision>
      <origin rpy="0 0 0" xyz="0.121 -0.128506 0.00113" />
      <geometry>
        <mesh filename="meshes/FR_thigh.stl" scale="0.001 0.001 0.001" />
      </geometry>
    </collision> -->
  </link>
  <link name="RR_thigh">
    <inertial>
      <origin xyz="0.045547 0.047995 -0.007447"/>
      <mass value="2.226976"/>
      <inertia ixx="0.00428900" ixy="-0.00242400" ixz="0.00381700"
              iyy="0.02280000" iyz="0.00050890" izz="0.02121000"/>
    </inertial>
    <visual>
      <origin rpy="0 0 0" xyz="-0.481 -0.125506 0.00113" />
      <geometry>
        <mesh filename="meshes/RR_thigh.stl" scale="0.001 0.001 0.001" />
      </geometry>
      <material name="silver" />
    </visual>
    <!-- <collision>
      <origin rpy="0 0 0" xyz="-0.481 -0.125506 0.00113" />
      <geometry>
        <mesh filename="meshes/RR_thigh.stl" scale="0.001 0.001 0.001" />
      </geometry>
    </collision> -->
  </link>
  <link name="FL_thigh">
    <inertial>
      <origin xyz="0.041849 -0.047206 -0.007427"/>
      <mass value="2.226916"/>
      <inertia ixx="0.00424000" ixy="0.00242400" ixz="0.00381900"
              iyy="0.02273000" iyz="-0.00050870" izz="0.02120000"/>
    </inertial>
    <visual>
      <origin rpy="0 0 0" xyz="0.121 0.126294 0.00113" />
      <geometry>
        <mesh filename="meshes/FL_thigh.stl" scale="0.001 0.001 0.001" />
      </geometry>
      <material name="silver" />
    </visual>
    <!-- <collision>
      <origin rpy="0 0 0" xyz="0.121 0.126294 0.00113" />
      <geometry>
        <mesh filename="meshes/FL_thigh.stl" scale="0.001 0.001 0.001" />
      </geometry>
    </collision> -->
  </link>
  <link name="RL_thigh">
    <inertial>
      <origin xyz="0.045549 -0.047206 -0.007427"/>
      <mass value="2.226916"/>
      <inertia ixx="0.00424000" ixy="0.00242400" ixz="0.00381900"
              iyy="0.02273000" iyz="-0.00050870" izz="0.02120000"/>
    </inertial>
    <visual>
      <origin rpy="0 0 0" xyz="-0.481 0.126294 0.00113" />
      <geometry>
        <mesh filename="meshes/RL_thigh.stl" scale="0.001 0.001 0.001" />
      </geometry>
      <material name="silver" />
    </visual>
    <!-- <collision>
      <origin rpy="0 0 0" xyz="-0.481 0.126294 0.00113" />
      <geometry>
        <mesh filename="meshes/RL_thigh.stl" scale="0.001 0.001 0.001" />
      </geometry>
    </collision> -->
  </link>
  <link name="RR_calf">
    <inertial>
      <origin xyz="-0.152659 0.011317 -0.003568"/>
      <mass value="0.403541"/>
      <inertia ixx="0.00006653" ixy="0.00000815" ixz="0.00014770"
              iyy="0.00538400" iyz="-0.00000100" izz="0.00534900"/>
    </inertial>
    <visual>
      <origin rpy="0 0 0" xyz="-0.170833 0.207494 0.070655" />
      <geometry>
        <mesh filename="meshes/RR_calf.stl" scale="0.001 0.001 0.001" />
      </geometry>
      <material name="silver" />
    </visual>
    <collision>
      <origin xyz="-0.31 0.01 -0.02" rpy="0 0 0"/>
      <geometry>
        <sphere radius="0.015"/>
      </geometry>
    </collision>
  </link>
  <link name="FR_calf">
    <inertial>
      <origin xyz="-0.156359 0.008317 -0.003568"/>
      <mass value="0.403541"/>
      <inertia ixx="0.00006653" ixy="0.00000815" ixz="0.00014770"
              iyy="0.00538400" iyz="-0.00000100" izz="0.00534900"/>
    </inertial>
    <visual>
      <origin rpy="0 0 0" xyz="-0.772833 0.207494 0.070655" />
      <geometry>
        <mesh filename="meshes/FR_calf.stl" scale="0.001 0.001 0.001" />
      </geometry>
      <material name="silver" />
    </visual>
    <collision>
      <origin xyz="-0.31 0.01 -0.02" rpy="0 0 0"/>
      <geometry>
        <sphere radius="0.015"/>
      </geometry>
    </collision>
  </link>
  <link name="RL_calf">
    <inertial>
      <origin xyz="-0.152659 0.009471 -0.003568"/>
      <mass value="0.403540"/>
      <inertia ixx="0.00006655" ixy="-0.00000815" ixz="0.00014770"
              iyy="0.00538400" iyz="0.00000100" izz="0.00534900"/>
    </inertial>
    <visual>
      <origin rpy="0 0 0" xyz="-0.772833 0.207494 0.070655" />
      <geometry>
        <mesh filename="meshes/RL_calf.stl" scale="0.001 0.001 0.001" />
      </geometry>
      <material name="silver" />
    </visual>
    <collision>
      <origin xyz="-0.31 0.01 -0.02" rpy="0 0 0"/>
      <geometry>
        <sphere radius="0.015"/>
      </geometry>
    </collision>
  </link>
  <link name="FL_calf">
    <inertial>
      <origin xyz="-0.156359 0.009471 -0.003568"/>
      <mass value="0.403540"/>
      <inertia ixx="0.00006655" ixy="-0.00000815" ixz="0.00014770"
              iyy="0.00538400" iyz="0.00000100" izz="0.00534900"/>
    </inertial>
    <visual>
      <origin rpy="0 0 0" xyz="-0.170833 0.207494 0.070655" />
      <geometry>
        <mesh filename="meshes/FL_calf.stl" scale="0.001 0.001 0.001" />
      </geometry>
      <material name="silver" />
    </visual>
    <collision>
      <origin xyz="-0.31 0.01 -0.02" rpy="0 0 0"/>
      <geometry>
        <sphere radius="0.015"/>
      </geometry>
    </collision>
  </link>

  <!-- <joint name="floating_trunk" type="floating">
    <parent link="base"/>
    <child link="trunk"/>
    <origin xyz="0 0 0.0" rpy="0 0 0"/>
  </joint> -->
  <joint name="world_to_base_rotX180" type="fixed">
    <parent link="world"/>
    <child  link="trunk"/>  <!-- your original root/base link -->
    <origin xyz="0 0 0" rpy="0 0 3.141592653589793"/>
  </joint>
  <joint name="FL_hip_joint" type="revolute">
    <origin rpy="0 0 0" xyz="-0.059 -0.098894 -0.00113" />
    <parent link="trunk" />
    <child link="FL_hip" />
    <axis xyz="-1.0 0.0 0.0" />
    <limit lower="-3.14" upper="3.14" />
  </joint>
  <joint name="RL_hip_joint" type="revolute">
    <origin rpy="0 0 0" xyz="0.419 -0.098894 -0.00113" />
    <parent link="trunk" />
    <child link="RL_hip" />
    <axis xyz="1.0 -0.0 -0.0" />
    <limit lower="-3.14" upper="3.14" />

  </joint>
  <joint name="RR_hip_joint" type="revolute">
    <origin rpy="0 0 0" xyz="0.419 0.101106 -0.00113" />
    <parent link="trunk" />
    <child link="RR_hip" />
    <axis xyz="1.0 -0.0 0.0" />
    <limit lower="-3.14" upper="3.14" />
  </joint>
  <joint name="FR_hip_joint" type="revolute">
    <origin rpy="0 0 0" xyz="-0.059 0.101106 -0.00113" />
    <parent link="trunk" />
    <child link="FR_hip" />
    <axis xyz="-1.0 0.0 -0.0" />
    <limit lower="-3.14" upper="3.14" />
  </joint>
  <joint name="FR_thigh_joint" type="revolute">
    <origin rpy="0 0 0" xyz="-0.062 0.0274 0.0" />
    <parent link="FR_hip" />
    <child link="FR_thigh" />
    <axis xyz="0.0 1.0 -0.0" />
    <limit lower="-1.5708" upper="1.5708" />
  </joint>
  <joint name="RR_thigh_joint" type="revolute">
    <origin rpy="0 0 0" xyz="0.062 0.0244 0.0" />
    <parent link="RR_hip" />
    <child link="RR_thigh" />
    <axis xyz="-0.0 1.0 0.0" />
    <limit lower="-1.5708" upper="1.5708" />
  </joint>
  <joint name="FL_thigh_joint" type="revolute">
    <origin rpy="0 0 0" xyz="-0.062 -0.0274 0.0" />
    <parent link="FL_hip" />
    <child link="FL_thigh" />
    <axis xyz="0.0 -1.0 -0.0" />
    <limit lower="-1.5708" upper="1.5708" />
  </joint>
  <joint name="RL_thigh_joint" type="revolute">
    <origin rpy="0 0 0" xyz="0.062 -0.0274 0.0" />
    <parent link="RL_hip" />
    <child link="RL_thigh" />
    <axis xyz="-0.0 -1.0 -0.0" />
    <limit lower="-1.5708" upper="1.5708" />
  </joint>
  <joint name="FL_calf_joint" type="revolute">
    <origin rpy="0 0 0" xyz="0.291833 -0.0812 -0.069525" />
    <parent link="FL_thigh" />
    <child link="FL_calf" />
    <axis xyz="-0.0 -1.0 0.0" />
    <limit lower="0.0" upper="2.30" />
  </joint>
  <joint name="RL_calf_joint" type="revolute">
    <origin rpy="0 0 0" xyz="0.291833 -0.0812 -0.069525" />
    <parent link="RL_thigh" />
    <child link="RL_calf" />
    <axis xyz="-0.0 -1.0 0.0" />
    <limit lower="0.0" upper="2.30" />
  </joint>
  <joint name="RR_calf_joint" type="revolute">
    <origin rpy="0 0 0" xyz="0.291833 0.0612 -0.069525" />
    <parent link="RR_thigh" />
    <child link="RR_calf" />
    <axis xyz="0.0 1.0 0.0" />
    <limit lower="-2.30" upper="0.0" />
  </joint>
  <joint name="FR_calf_joint" type="revolute">
    <origin rpy="0 0 0" xyz="0.291833 0.0612 -0.069525" />
    <parent link="FR_thigh" />
    <child link="FR_calf" />
    <axis xyz="0.0 1.0 -0.0" />
    <limit lower="-2.30" upper="0.0" />
  </joint>


  <link name="imu_link">
  <visual>
    <origin xyz="0 0 0"/>
    <geometry>
      <sphere radius="0.01"/>
    </geometry>
    <material name="gray"/>
  </visual>
</link>

<joint name="imu_joint" type="fixed">
  <parent link="trunk"/>
  <child link="imu_link"/>
  <origin xyz="0 0 0" rpy="0 0 0"/>
</joint>
</robot>